#bug1

2023-06-14 11:36:58.620 Uncaught app exception

Traceback (most recent call last):

  File "/home/appuser/venv/lib/python3.9/site-packages/streamlit/runtime/scriptrunner/script_runner.py", line 552, in _run_script

    exec(code, module.__dict__)

  File "/app/04_qupath_contour_to_lmd/streamlit_app.py", line 47, in <module>

    dataframe_to_xml_v2(uploaded_file, calibration_points)

  File "/app/04_qupath_contour_to_lmd/python_functions.py", line 22, in dataframe_to_xml_v2

    df = geopandas.read_file(input_file)

  File "/home/appuser/venv/lib/python3.9/site-packages/geopandas/io/file.py", line 281, in _read_file

    return _read_file_fiona(

  File "/home/appuser/venv/lib/python3.9/site-packages/geopandas/io/file.py", line 322, in _read_file_fiona

    with reader(path_or_bytes, **kwargs) as features:

  File "/home/appuser/venv/lib/python3.9/site-packages/fiona/env.py", line 457, in wrapper

    return f(*args, **kwds)

  File "/home/appuser/venv/lib/python3.9/site-packages/fiona/__init__.py", line 289, in open

    path = parse_path(fp)

  File "/home/appuser/venv/lib/python3.9/site-packages/fiona/path.py", line 136, in parse_path

    elif path.startswith('/vsi'):

AttributeError: 'NoneType' object has no attribute 'startswith'